[ 2023-05-16 00:05:24,020 ] 22 root - INFO: PREDICTION PIPELINE INITIATED
[ 2023-05-16 00:05:24,773 ] 26 root - INFO: INPUT OBTAINED AS [{'ID': 0, 'Delivery_person_ID': 'DEHRES17DEL01', ' Delivery_person_Age': 34, ' Delivery_person_Ratings': 3.5, 'Restaurant_latitude': 30.327968, 'Restaurant_longitude': 78.046106, 'Delivery_location_latitude': 30.397968, 'Delivery_location_longitude': 78.116106, 'Order_Date': '5-15-2023', 'Time_Orderd': '7:11:20', 'Time_Order_picked': '7:23:20', 'Weather_conditions': 'Stormy', 'Road_traffic_density': 'Medium', 'Vehicle_condition': 0, 'Type_of_order': 'Meal', 'Type_of_vehicle': 'scooter', 'multiple_deliveries': 1.0, 'Festival': 'Yes', 'City': 'Metropolitan'}]
[ 2023-05-16 00:05:24,774 ] 19 root - INFO: Input values ingestion INITIATED
[ 2023-05-16 00:05:24,775 ] 23 root - INFO: input dictionary loaded as a dataframe
[ 2023-05-16 00:05:24,775 ] 26 root - INFO: CALLING utils for cleaning in Predictor.ingest at prediction.py
[ 2023-05-16 00:05:24,775 ] 29 root - INFO: df RECEIVED for cleaning in clean() at data_preparation_utils.py, shape: (1, 19)
[ 2023-05-16 00:05:24,776 ] 31 root - INFO: ID column dropped
[ 2023-05-16 00:05:24,777 ] 39 root - INFO: Records with faulty time dropped
[ 2023-05-16 00:05:24,777 ] 41 root - INFO: df cleaning COMPLETE in clean() at data_preparation_utils.py, shape: (1, 18), and returned
[ 2023-05-16 00:05:24,778 ] 28 root - INFO: RECEIVED input dataframe cleaned
[ 2023-05-16 00:05:24,778 ] 31 root - INFO: CALLING utils for feature engineering in Predictor.ingest at prediction.py
[ 2023-05-16 00:05:24,778 ] 89 root - INFO: df received for Feature engineering, shape: (0, 18) in apply_feature_engineering() at data_preparation_utils.py
[ 2023-05-16 00:05:24,778 ] 92 root - INFO: Time_Orderd and Time_Order_picked columns converted to hours
[ 2023-05-16 00:05:24,780 ] 97 root - INFO: Order_Date split to Order_Day and Order_Month
[ 2023-05-16 00:05:24,781 ] 103 root - INFO: Geo_Distance column added
[ 2023-05-16 00:05:24,781 ] 105 root - INFO: df feature engineering steps complete in apply_feature_engineering() at data_preparation_utils.py, shape: (0, 20), and returned
[ 2023-05-16 00:05:24,781 ] 33 root - INFO: RECEIVED input dataframe feature engineered
[ 2023-05-16 00:05:24,781 ] 36 root - INFO: CALLING utils for transformation in Predictor.ingest at prediction.py
[ 2023-05-16 00:05:24,781 ] 124 root - INFO: df RECEIVED for transformation in fit_to_transformations() at data_transformation_utils.py, train_shape:(0, 20)
[ 2023-05-16 00:05:24,781 ] 77 root - INFO: fetch request for [imputer] RECEIVED in get_preprocessor_from_shelve() at general_utils.py
[ 2023-05-16 00:05:24,800 ] 85 root - INFO: object [ColumnTransformer(transformers=[('numeric_imputer',
                                 SimpleImputer(strategy='median'),
                                 ['Delivery_person_Age',
                                  'Delivery_person_Ratings',
                                  'Restaurant_latitude', 'Restaurant_longitude',
                                  'Delivery_location_latitude',
                                  'Delivery_location_longitude', 'Time_Orderd',
                                  'Time_Order_picked', 'Vehicle_condition',
                                  'multiple_deliveries', 'Order_Day',
                                  'Order_Month', 'Geo_Distance']),
                                ('categoric_imputation',
                                 SimpleImputer(strategy='most_frequent'),
                                 ['Delivery_person_ID', 'Weather_conditions',
                                  'Road_traffic_density', 'Type_of_order',
                                  'Type_of_vehicle', 'Festival', 'City'])])] of type [<class 'sklearn.compose._column_transformer.ColumnTransformer'>] retrieved and RETURNED from preprosessor shelve
[ 2023-05-16 00:05:24,801 ] 166 root - CRITICAL: Exception logged from file [c:\users\u1143589\learning\ineuron\ml\food_delivery_time\src\utils\data_transformation_utils.py] line no. [136] with message ["['Delivery_person_Age', 'Delivery_person_Ratings'] not in index"]
[ 2023-05-16 00:05:24,801 ] 45 root - CRITICAL: Exception logged from file [c:\users\u1143589\learning\ineuron\ml\food_delivery_time\src\components\prediction.py] line no. [37] with message [Exception logged from file [c:\users\u1143589\learning\ineuron\ml\food_delivery_time\src\utils\data_transformation_utils.py] line no. [136] with message ["['Delivery_person_Age', 'Delivery_person_Ratings'] not in index"]]
